Workbook
Name 머릿글: TestCase!$B$1:$K$1

Sheet TestCase
A1: No | B1: 대분류 | C1: 중분류 | D1: 소분류 | E1: 테스트 시나리오 | F1: 테스트 조건 | G1: 실행 순서 | H1: Pass Result | I1: P/F | J1: 실제 결과 | K1: 비고 | L1: Tag
A2: =ROW()-2 -> 0 | B2: 게임실행 | C2: 실행 | D2: 게임실행 | E2: 클라이언트를 실행한다 | G2: 1. "Operation:Snackstorm.exe" 파일실행 | H2: 타이틀 화면이 정상적으로 표시 | I2: Pass | J2: 실행됨 | K2: Pass: 테스트 성공 | L2: =IF(B2="",L1,B2) -> 게임실행
C3: 실행 | D3: 버전확인 | E3: 타이틀 하단에 표시되는 빌드 버전이 문서의 버전과 일치하는지 확인한다 | F3: 타이틀화면 진입 | G3: 1. 하단 버전 표기 확인 | H3: 빌드 버전이 기획문서와 동일하다 | I3: Fail | J3: 안나옴 | K3: 안함
C4: 윈도우기능 | D4: 제목/아이콘 표시 | E4: 좁은창에서 제목표시줄 내용을 확인한다 | F4: 타이틀화면 진입 | G4: 1. 윈도우 타이틀바를 확인한다 | H4: 된다. | I4: Block | J4: 안나옴 | K4: 타이틀 없음 | L4: =IF(B5="",L2,B5) -> 게임실행
A5: =ROW()-2 -> 3 | E5: 넓은창에서 제목표시줄을 내용을 확인한다 | F5: 타이틀화면 진입 | G5: 1. 윈도우 타이틀바를 확인한다 | H5: 된다 | I5: Block | J5: 안나옴 | K5: 작은 타이틀 없음 | L5: =IF(B6="",L4,B6) -> 게임실행
A6: =ROW()-2 -> 4 | D6: 최소화 | E6: 윈도우를 최소화 후 복귀한다 | F6: 인게임 시작전 | G6: 1. 윈도우 최소화버튼 클릭 2. 윈도우 작업표시줄에서 클릭 | H6: 1. 게임이 최소화 되었다 복구된다 | I6: N/A | J6: 나옴 | K6: 성공 | L6: =IF(B7="",L5,B7) -> 게임실행
A7: =ROW()-2 -> 5 | E7: 게임중 윈도우를 최소화 후 복귀한다 | F7: 인게임 시작후 | G7: 1. 윈도우 최소화버튼 클릭 2. 일정 시간 대기(대략 3초) 2. 윈도우 작업표시줄에서 지뢰찾기 클릭 | H7: 1. 게임이 최소화 되었다 복구된다 2. 진행중이던 게임의 카운터가 최소화 시간 동안 멈춰있는다 | I7: N/T | J7: 돌아옴 | K7: 성공 | L7: =IF(B9="",L6,B9) -> 게임실행
D8: 종료 | E8: Alt+F4를 눌러 즉시 끈다 | G8: 1. 윈도우 최소화버튼 클릭 | H8: 1. 게임이 최소화 되었다 복구된다 2. 진행중이던 게임의 카운터가 최소화 시간 동안 멈춰있는다 | I8: Pass | J8: 꺼진다 | K8: 성공
A9: =ROW()-2 -> 7 | D9: 닫기 | E9: 윈도우를 닫는다 | G9: 1. 윈도우 닫기 | H9: 1. 게임이 최소화 되었다 복구된다 2. 진행중이던 게임의 카운터가 최소화 시간 동안 멈춰있는다 | I9: Pass | J9: 된다 | K9: 성공 | L9: =IF(B10="",L7,B10) -> 게임실행
A10: =ROW()-2 -> 8 | D10: 이름 생성 | E10: 이름을 입력한다 | G10: 1.이름을 입력한다 | H10: 다음화면으로 넘어간다 | I10: Pass | J10: 입력한다 | K10: 성공 | L10: =IF(B11="",L9,B11) -> 메뉴기능
A11: =ROW()-2 -> 9 | B11: 메뉴기능 | C11: 로비 | D11: 방생성 | E11: 방을 생성한다 | F11: 이름을 생성한 후 | G11: 1.방 생성을 한후 2.이름을 입력한다 3.생성을 누른다 | H11: 대기실 화면이 보인다 | I11: Pass | J11: 방을 생성했다 | K11: 성공 | L11: =IF(B12="",L10,B12) -> 메뉴기능
A12: =ROW()-2 -> 10 | D12: 방찾기 | E12: 방을 들어간다 | F12: 이미 생성된 방이 있을경우 | G12: 1.대기실을 누른다 | H12: 대기실 화면이 보인다 | I12: Pass | J12: 방에 들어갔다 | K12: 성공 | L12: =IF(B13="",L11,B13) -> 메뉴기능
A13: =ROW()-2 -> 11 | D13: 네트워크 끊김 복구 | E13: 연결이 끊겼을 때 다시 연결되는지 확인한다 | G13: 1. 기다린다 | H13: 다시 연결된다 | I13: N/T | J13: 연결 못 끊음 | K13: 다행 | L13: =IF(B14="",L12,B14) -> 메뉴기능
A14: =ROW()-2 -> 12 | D14: 행동 취소 | E14: 행동을 취소한다 | F14: 생성을 하기 전에 | G14: 1.esc를 누른다 2.x ui를 누른다 | H14: ui 창이 꺼진다. | I14: Pass | J14: 안됨 | K14: 안함 | L14: =IF(B15="",L13,B15) -> 인게임기능
A15: =ROW()-2 -> 13 | B15: 인게임기능 | C15: 1라운드 | D15: 게임시작 | E15: 1라운드가 시작한다 | F15: 대기실에 들어간 후 | H15: 타이머 작동 | I15: Pass | J15: 타이머 작동 | K15: 성공 | L15: =IF(B16="",L14,B16) -> 인게임기능
A16: =ROW()-2 -> 14 | D16: 카운트 | E16: 게임 카운트가 시작된다 | F16: 인게임 시작전 | G16: 1. 오른쪽 상단에 숫자가 준다 | H16: 숫자가 줄어든다 | I16: Pass | J16: 90초부터 하락 | K16: 성공 | L16: =IF(B17="",L15,B17) -> 인게임기능
A17: =ROW()-2 -> 15 | E17: 타이머가 종료되는가 | F17: 인게임 시작후 | G17: 1. 오른쪽 상단에 숫자가 0가 된다. | H17: 숫자가 0이 되고 다음 라운드를 기다린다 | I17: Pass | J17: 종료된다 | K17: 성공 | L17: =IF(B18="",L16,B18) -> 인게임기능
A18: =ROW()-2 -> 16 | D18: 아이템 구매 | E18: 매점 아이템을 구매한다 | G18: 1.매점에서 npc를 클릭한다 2.살 아이템을 고른다. | H18: 아이템이 나온다 | I18: Pass | J18: 아이템이 나온다 | K18: 성공 | L18: =IF(B19="",L17,B19) -> 인게임기능
A19: =ROW()-2 -> 17 | E19: 자판기 아이템을 구매한다 | G19: 1. 자판기를 클릭한다. 2. 살 간식의 버튼을 누른다 | H19: 아이템이 나온다 | I19: N/A | J19: 자판기가 없다 | K19: 제작중 | L19: =IF(B21="",L18,B21) -> 인게임기능
D20: 인벤토리 | E20: 인벤토리가 열린다 | G20: e키를 누른다 | H20: ui 가 뜬다 | I20: Pass | J20: ui가 열린다 | K20: 성공
A21: =ROW()-2 -> 19 | E21: 인벤토리가 제한 된다 | G21: 1. 간식을 먹어 아이템을 다 채운다. 2.e키를 눌러 확인한다. 3. 아이템을 본다 | H21: 아이템이 먹어지지 않는다 | I21: Pass | J21: 제한된다 | K21: 성공 | L21: =IF(B22="",L19,B22) -> 인게임기능
A22: =ROW()-2 -> 20 | D22: 아이템 드랍 | E22: 아이템을 드랍한다 | F22: 아이템을 먹은 후 | G22: 1.e키를 눌러 인벤토리를 연다. 2.떨어뜨릴 아이템을 누른다 | H22: 아이템을 손에 든다 | I22: N/A | J22: 클릭이 안됨 | K22: 제작중 | L22: =IF(B23="",L21,B23) -> 인게임기능
A23: =ROW()-2 -> 21 | E23: 드랍된 아이템을 회수할 수 있다 | G23: 1.인벤토리에서 아이템을 든다. 2. 아이템을 떨어뜨린다. 3. 아이템을 집는다 | H23: 아이템이 인벤토리에 들어온다 | I23: Block | J23: 드랍이 안됨 | K23: 제작중 | L23: =IF(B24="",L22,B24) -> 인게임기능
A24: =ROW()-2 -> 22 | D24: 상벌점 | E24: 벌점이 부여된다 | G24: 1. 미니게임을 한다, 1.규칙을 위반한다. 2. 벌점을 받는다 | H24: 벌점이 부여된 ui 가 뜬다 | I24: N/A | J24: 없음 | K24: 제작중 | L24: =IF(B25="",L23,B25) -> 인게임기능
A25: =ROW()-2 -> 23 | E25: 상점이 부여된다 | G25: 1. 미니게임을 한다, 2. 성공한다 | H25: 상점이 부여된 ui가 뜬다 | I25: N/A | J25: 없음 | K25: 제작중 | L25: =IF(B26="",L24,B26) -> 인게임기능
A26: =ROW()-2 -> 24 | D26: 점수 | E26: 점수판이 나온다 | G26: 라운드가 전부 끝난다 | H26: 적용된 결과가 나온다 | I26: Pass | J26: 결과가 나온다 | K26: 성공 | L26: =IF(B27="",#REF!,B27) -> #REF!
A27: =ROW()-2 -> 25 | D27: 미니게임 | E27: 미니게임이 진행된다 | G27: 시간이 끝날 때 까지 게임 진행 | H27: 된다 | I27: Pass | J27: 된다 | K27: 제작중 | L27: =IF(B28="",L26,B28) -> #REF!
A28: =ROW()-2 -> 26 | D28: ai | E28: ai가 인식한다 | G28: npc 만날 때 까지 게임 진행 | H28: npc 가 따라오기 시작 | I28: Pass | J28: npc가 따라옴 | K28: 성공 | L28: =IF(B29="",L27,B29) -> #REF!
A29: =ROW()-2 -> 27 | E29: ai가 움직인다 | G29: 1. npc를 만난다 2.npc 범위 안으로 들어간다 | H29: npc가 움직인다 | I29: Pass | J29: npc가 움직임 | K29: 성공
A30: =ROW()-2 -> 28 | E30: ai에게 잡힌다 | G30: 1. npc 범위 안으로 들어간다. 2. npc와 가까워진다. | H30: 교실로 돌아와지고 아이템이 사라진다. | I30: N/A | J30: 통과하여 지나감 | K30: 제작중 | L30: =IF(B30="",L29,B30) -> 0
C31: 2라운드 | D31: 리셋 | E31: 인벤토리의 아이템이 리셋된다 | F31: 1라운드가 끝났을 때 | G31: 1. 2라운드에 인벤토리를 확인한다 | H31: 아이템이 전부 사라진다 | I31: Pass | J31: 아이템이 사라짐 | K31: 성공 | L31: =IF(B32="",L30,B32) -> 0
E32: 툴바의 아이템을 확인한다. | F32: 1라운드가 끝났을 때 | G32: 1. 2라운드에 툴바를 확인한다. | H32: 아이템이 적용되고 돌아온다 | I32: N/A | J32: 개수가 안나옴 | K32: 제작중 | L32: =IF(B33="",L31,B33) -> 0
A33: =ROW()-2 -> 31 | D33: 게임시작 | E33: 2라운드가 시작한다 | F33: 대기실에 들어간 후 | H33: 타이머 작동 | I33: Pass | J33: 타이머 작동 | K33: 성공 | L33: =IF(B34="",#REF!,B34) -> #REF!
A34: =ROW()-2 -> 32 | D34: 카운트 | E34: 게임 카운트가 시작된다 | F34: 인게임 시작전 | G34: 1. 오른쪽 상단에 숫자가 준다 | H34: 숫자가 줄어든다 | I34: Pass | J34: 90초부터 하락 | K34: 성공 | L34: =IF(B35="",L33,B35) -> #REF!
A35: =ROW()-2 -> 33 | E35: 타이머가 종료되는가 | F35: 인게임 시작후 | G35: 1. 오른쪽 상단에 숫자가 0가 된다. | H35: 숫자가 0이 되고 다음 라운드를 기다린다 | I35: Pass | J35: 종료된다 | K35: 성공 | L35: =IF(B36="",L34,B36) -> #REF!
A36: =ROW()-2 -> 34 | D36: 아이템 구매 | E36: 매점 아이템을 구매한다 | G36: 1.매점에서 npc를 클릭한다 2.살 아이템을 고른다. | H36: 아이템이 나온다 | I36: Pass | J36: 아이템이 나온다 | K36: 성공 | L36: =IF(B37="",L35,B37) -> #REF!
A37: =ROW()-2 -> 35 | E37: 자판기 아이템을 구매한다 | G37: 1. 자판기를 클릭한다. 2. 살 간식의 버튼을 누른다 | H37: 아이템이 나온다 | I37: N/A | J37: 자판기가 없다 | K37: 제작중 | L37: =IF(B39="",L36,B39) -> #REF!
A38: =ROW()-2 -> 36 | D38: 인벤토리 | E38: 인벤토리가 열린다 | G38: e키를 누른다 | H38: ui 가 뜬다 | I38: Pass | J38: ui가 열린다 | K38: 성공 | L38: =IF(B39="",L37,B39) -> #REF!
A39: =ROW()-2 -> 37 | E39: 인벤토리가 제한 된다 | G39: 1. 간식을 먹어 아이템을 다 채운다. 2.e키를 눌러 확인한다. 3. 아이템을 본다 | H39: 아이템이 먹어지지 않는다 | I39: Pass | J39: 제한된다 | K39: 성공 | L39: =IF(B40="",L37,B40) -> #REF!
A40: =ROW()-2 -> 38 | D40: 아이템 드랍 | E40: 아이템을 드랍한다 | F40: 아이템을 먹은 후 | G40: 1.e키를 눌러 인벤토리를 연다. 2.떨어뜨릴 아이템을 누른다 | H40: 아이템을 손에 든다 | I40: N/A | J40: 클릭이 안됨 | K40: 제작중 | L40: =IF(B41="",L39,B41) -> #REF!
...

Sheet TC MAP
A1: 테스트케이스 현황
A2: 분류 | B2: 개수 | C2: 비율 | D2: Pass | E2: Fail | F2: N/A | G2: Block | H2: N/T | I2: Total | J2: Total(%)
A3: 게임실행 | B3: 9 | C3: =IFERROR(B3/$B$7,0) -> 0.1011236 | D3: 4 | E3: 1 | F3: =COUNTIFS(TestCase!$I:$I,"*"&F$2&"*",TestCase!$L:$L,$A3) -> 1 | G3: =COUNTIFS(TestCase!$I:$I,"*"&G$2&"*",TestCase!$L:$L,$A3) -> 2 | H3: =COUNTIFS(TestCase!$I:$I,"*"&H$2&"*",TestCase!$L:$L,$A3) -> 1 | I3: 9 | J3: =I3/B3 -> 1
A4: 메뉴기능 | B4: =COUNTIF(TestCase!L:L,A4) -> 4 | C4: =IFERROR(B4/$B$7,0) -> 0.04494382 | D4: =COUNTIFS(TestCase!$I:$I,"*"&D$2&"*",TestCase!$L:$L,$A4) -> 3 | E4: =COUNTIFS(TestCase!$I:$I,"*"&E$2&"*",TestCase!$L:$L,$A4) -> 0 | F4: =COUNTIFS(TestCase!$I:$I,"*"&F$2&"*",TestCase!$L:$L,$A4) -> 0 | G4: =COUNTIFS(TestCase!$I:$I,"*"&G$2&"*",TestCase!$L:$L,$A4) -> 0 | H4: =COUNTIFS(TestCase!$I:$I,"*"&H$2&"*",TestCase!$L:$L,$A4) -> 1 | I4: =SUM(D4:H4) -> 4 | J4: =I4/B4 -> 1
A5: 인게임기능 | B5: 52 | C5: =IFERROR(B5/$B$7,0) -> 0.58426966 | D5: 31 | E5: =COUNTIFS(TestCase!$I:$I,"*"&E$2&"*",TestCase!$L:$L,$A5) -> 0 | F5: 18 | G5: 3 | H5: =COUNTIFS(TestCase!$I:$I,"*"&H$2&"*",TestCase!$L:$L,$A5) -> 0 | I5: =SUM(D5:H5) -> 52 | J5: =I5/B5 -> 1
A6: 네트워크 | B6: 24 | C6: =IFERROR(B6/$B$7,0) -> 0.26966292 | D6: 20 | E6: =COUNTIFS(TestCase!$I:$I,"*"&E$2&"*",TestCase!$L:$L,$A6) -> 0 | F6: =COUNTIFS(TestCase!$I:$I,"*"&F$2&"*",TestCase!$L:$L,$A6) -> 0 | G6: =COUNTIFS(TestCase!$I:$I,"*"&G$2&"*",TestCase!$L:$L,$A6) -> 0 | H6: 4 | I6: =SUM(D6:H6) -> 24 | J6: =I6/B6 -> 1
A7: Total | B7: =SUM(B3:B6) -> 89 | C7: =SUM(C3:C6)/SUM($C$3:$C$6) -> 1 | D7: =SUM(D3:D6) -> 58 | E7: =SUM(E3:E6) -> 1 | F7: =SUM(F3:F6) -> 19 | G7: =SUM(G3:G6) -> 5 | H7: =SUM(H3:H6) -> 6 | I7: =SUM(I3:I6) -> 89
A8: Total(%) | D8: =D7/$B7 -> 0.65168539 | E8: =E7/$B7 -> 0.011235955 | F8: =F7/$B7 -> 0.21348315 | G8: =G7/$B7 -> 0.056179775 | H8: =H7/$B7 -> 0.06741573 | I8: =I7/$B7 -> 1
